Workbook
Name Slicer_ABA_VERIFIED: #N/A
Name Slicer_region: #N/A
Name Slicer_STATE_FULL: #N/A

Sheet Descriptive Dashboard
A2: NIRD Burn Dashboard
A3: Evaluating Burn Trauma cases in the US
D9: State | E9: Burn Beds Adult | F9: Burn Beds Peds | G9: Beds dedicated to burn care | H9: Total staffed hospital beds
D10: Texas | E10: 8 | F10: 6 | G10: 206 | H10: 22794
D11: California | E11: 12 | F11: 11 | G11: 140 | H11: 22552
D12: Florida | E12: 6 | F12: 2 | G12: 85 | H12: 19224
D13: New York | E13: 10 | F13: 7 | G13: 143 | H13: 18413
D14: Illinois | E14: 5 | F14: 4 | G14: 77 | H14: 18258
D15: Michigan | E15: 5 | F15: 3 | G15: 69 | H15: 16872
D16: Pennsylvania | E16: 6 | F16: 3 | G16: 83 | H16: 15191
D17: Ohio | E17: 6 | F17: 4 | G17: 94 | H17: 14406
D18: Missouri | E18: 5 | F18: 5 | G18: 93 | H18: 9605
D19: Georgia | E19: 3 | F19: 3 | G19: 129 | H19: 8153
D20: North Carolina | E20: 2 | F20: 2 | G20: 60 | H20: 7360
D21: Virginia | E21: 3 | F21: 2 | G21: 68 | H21: 7153
D22: Connecticut | E22: 1 | G22: 9 | H22: 6652
D23: Colorado | E23: 3 | F23: 2 | G23: 52 | H23: 6332
D24: Arizona | E24: 2 | F24: 2 | G24: 80 | H24: 6110
D25: New Jersey | E25: 1 | F25: 1 | G25: 12 | H25: 6037
D26: Massachusetts | E26: 2 | F26: 1 | G26: 52 | H26: 5719
D27: Minnesota | E27: 3 | F27: 3 | G27: 50 | H27: 5293
D28: Wisconsin | E28: 2 | F28: 3 | G28: 28 | H28: 4839
D29: Indiana | E29: 3 | F29: 3 | G29: 41 | H29: 4659
D30: South Carolina | E30: 1 | F30: 1 | G30: 25 | H30: 4337
D31: Tennessee | E31: 3 | F31: 2 | G31: 51 | H31: 4139
D32: Louisiana | E32: 4 | F32: 1 | G32: 47 | H32: 3739
D33: Alabama | E33: 2 | F33: 1 | G33: 52 | H33: 3559
D34: Kansas | E34: 2 | F34: 2 | G34: 28 | H34: 3212
... D39: Maryland | E39: 1 | F39: 1 | G39: 20 | H39: 2673
D40: West Virginia | E40: 1 | G40: 4 | H40: 2565
D41: Nebraska | E41: 1 | F41: 1 | G41: 16 | H41: 2366
D42: Iowa | E42: 1 | F42: 1 | G42: 17 | H42: 2296
D43: Mississippi | H43: 2237
D44: Nevada | E44: 2 | F44: 2 | G44: 31 | H44: 2073
D45: Kentucky | E45: 1 | G45: 16 | H45: 1997
D46: District of Columbia | E46: 1 | F46: 1 | G46: 41 | H46: 1920
D47: South Dakota | H47: 1507
D48: Idaho | E48: 1 | F48: 1 | G48: 15 | H48: 1471
D49: North Dakota | H49: 1453
D50: Montana | H50: 1357
...

Sheet Sheet1
A3: Region | B3: Quantity | C3: =MAX(B4:B7)*1.3 -> 1101.1 | D3: Create a help column using lamda of 1.3
A4: South | B4: 847 | C4: =$C$3-B4 -> 254.1
A5: Midwest | B5: 513 | C5: =$C$3-B5 -> 588.1
A6: West | B6: 406 | C6: =$C$3-B6 -> 695.1
A7: Northeast | B7: 314 | C7: =$C$3-B7 -> 787.1
A11: Once the doughnut chart is created, it can be pasted on the dashshboard

Sheet Sheet2
A3: Region | B3: Sum of Dedicated Burn Beds
A4: Midwest | B4: 513
A5: Northeast | B5: 314
A6: South | B6: 847
A7: West | B7: 406

Sheet Analysis
A1: ABA_VERIFIED | B1: (All) | R1: STATE | S1: (All)
W2: Distribution of burn centres and by census region and state population | AO2: STATE | AP2: MT
A3: Values | D3: Row Labels | E3: Sum of BURN_BEDS(beds dedicated to burn care) | R3: Row Labels | S3: Sum of BURN_BEDS(beds dedicated to burn care) | V3: State | W3: Dedicated Burn Beds | X3: Total population | Y3: Normalization | Z3: Region | AF3: Helper | AV3: Row Labels | AW3: Sum of TOTAL_BEDS(Total staffed hospital beds) | BF3: State | BG3: Dedicated Burn Beds | BH3: Total population | BI3: Normalization | BJ3: Region | BN3: Row Labels | BO3: Sum of Dedicated Burn Beds | BP3: Sum of Total population
A4: Sum of BURN_ADULT | B4: 39 | D4: Texas | E4: 206 | F4: {=D4:E53} -> Texas | G4: 206 | H4: =_xlfn.XLOOKUP(D4,'State Population (2026)'!B:B,'State Population (2026)'!C:C,0) -> 31709821 | R4: Texas | S4: 206 | V4: Texas | W4: 206 | X4: 31709821 | Y4: =(Table2[[#This Row],[Dedicated Burn Beds]]/Table2[[#This Row],[Total population]])*100000 -> 0.64964101 | Z4: =_xlfn.XLOOKUP(Table2[[#This Row],[State]],'[1]State Regions'!$A:$A,'[1]State Regions'!$B:$B) -> South | AB4: Row Labels | AC4: Sum of BURN_BEDS(beds dedicated to burn care) | AD4: Region | AE4: Dedicated beds | AF4: =MAX(AE5:AE8)*1.3 -> 1101.1 | AG4: Data Column | AI4: Sum of BURN_BEDS(beds dedicated to burn care) | AJ4: Column Labels | AP4: Column Labels | AV4: West | AW4: 50886 | BF4: Texas | BG4: 206 | BH4: 31709821 | BI4: =(Table24[[#This Row],[Dedicated Burn Beds]]/Table24[[#This Row],[Total population]])*100000 -> 0.64964101 | BJ4: =_xlfn.XLOOKUP(Table24[[#This Row],[State]],'[1]State Regions'!$A:$A,'[1]State Regions'!$B:$B) -> South | BN4: California | BO4: 140 | BP4: 39355309
A5: Sum of BURN_PEDS | B5: 24 | D5: New York | E5: 143 | F5: New York | G5: 143 | H5: =_xlfn.XLOOKUP(D5,'State Population (2026)'!B:B,'State Population (2026)'!C:C,0) -> 20002427 | R5: Georgia | S5: 129 | V5: New York | W5: 143 | X5: 20002427 | Y5: =(Table2[[#This Row],[Dedicated Burn Beds]]/Table2[[#This Row],[Total population]])*100000 -> 0.71491325 | Z5: =_xlfn.XLOOKUP(Table2[[#This Row],[State]],'[1]State Regions'!$A:$A,'[1]State Regions'!$B:$B) -> Northeast | AB5: South | AC5: 847 | AD5: {=AB5:AC8} -> South | AE5: 847 | AF5: =$AF$4-AE5 -> 254.1 | AG5: =AD5&"("&AE5&")" -> South(847) | AI5: Row Labels | AJ5: No | AK5: No data | AL5: Yes | AM5: Grand Total | AO5: Row Labels | AP5: Grand Total | AV5: California | AW5: 22552 | BF5: New York | BG5: 143 | BH5: 20002427 | BI5: =(Table24[[#This Row],[Dedicated Burn Beds]]/Table24[[#This Row],[Total population]])*100000 -> 0.71491325 | BJ5: =_xlfn.XLOOKUP(Table24[[#This Row],[State]],'[1]State Regions'!$A:$A,'[1]State Regions'!$B:$B) -> Northeast | BN5: Texas | BO5: 206 | BP5: 31709821
A6: Sum of BURN_BEDS(beds dedicated to burn care) | B6: 847 | D6: California | E6: 140 | F6: California | G6: 140 | H6: =_xlfn.XLOOKUP(D6,'State Population (2026)'!B:B,'State Population (2026)'!C:C,0) -> 39355309 | R6: Florida | S6: 85 | V6: California | W6: 140 | X6: 39355309 | Y6: =(Table2[[#This Row],[Dedicated Burn Beds]]/Table2[[#This Row],[Total population]])*100000 -> 0.35573345 | Z6: =_xlfn.XLOOKUP(Table2[[#This Row],[State]],'[1]State Regions'!$A:$A,'[1]State Regions'!$B:$B) -> West | AB6: Midwest | AC6: 513 | AD6: Midwest | AE6: 513 | AF6: =$AF$4-AE6 -> 588.1 | AG6: =AD6&"("&AE6&")" -> Midwest(513) | AI6: South | AJ6: 345 | AK6: 52 | AL6: 450 | AM6: 847 | AO6: Total Sum of BURN_BEDS(beds dedicated to burn care) | AV6: Colorado | AW6: 6332 | BF6: California | BG6: 140 | BH6: 39355309 | BI6: =(Table24[[#This Row],[Dedicated Burn Beds]]/Table24[[#This Row],[Total population]])*100000 -> 0.35573345 | BJ6: =_xlfn.XLOOKUP(Table24[[#This Row],[State]],'[1]State Regions'!$A:$A,'[1]State Regions'!$B:$B) -> West | BN6: Florida | BO6: 85 | BP6: 23462518
A7: Sum of TOTAL_BEDS(Total staffed hospital beds) | B7: 97185 | D7: Georgia | E7: 129 | F7: Georgia | G7: 129 | H7: =_xlfn.XLOOKUP(D7,'State Population (2026)'!B:B,'State Population (2026)'!C:C,0) -> 11302748 | R7: Virginia | S7: 68 | V7: Georgia | W7: 129 | X7: 11302748 | Y7: =(Table2[[#This Row],[Dedicated Burn Beds]]/Table2[[#This Row],[Total population]])*100000 -> 1.1413154 | Z7: =_xlfn.XLOOKUP(Table2[[#This Row],[State]],'[1]State Regions'!$A:$A,'[1]State Regions'!$B:$B) -> South | AB7: West | AC7: 406 | AD7: West | AE7: 406 | AF7: =$AF$4-AE7 -> 695.1 | AG7: =AD7&"("&AE7&")" -> West(406) | AI7: Grand Total | AJ7: 345 | AK7: 52 | AL7: 450 | AM7: 847 | AO7: Total Sum of TOTAL_BEDS(Total staffed hospital beds) | AV7: Arizona | AW7: 6110 | BF7: Georgia | BG7: 129 | BH7: 11302748 | BI7: =(Table24[[#This Row],[Dedicated Burn Beds]]/Table24[[#This Row],[Total population]])*100000 -> 1.1413154 | BJ7: =_xlfn.XLOOKUP(Table24[[#This Row],[State]],'[1]State Regions'!$A:$A,'[1]State Regions'!$B:$B) -> South | BN7: New York | BO7: 143 | BP7: 20002427
D8: Ohio | E8: 94 | F8: Ohio | G8: 94 | H8: =_xlfn.XLOOKUP(D8,'State Population (2026)'!B:B,'State Population (2026)'!C:C,0) -> 11900510 | R8: North Carolina | S8: 60 | V8: Ohio | W8: 94 | X8: 11900510 | Y8: =(Table2[[#This Row],[Dedicated Burn Beds]]/Table2[[#This Row],[Total population]])*100000 -> 0.78988211 | Z8: =_xlfn.XLOOKUP(Table2[[#This Row],[State]],'[1]State Regions'!$A:$A,'[1]State Regions'!$B:$B) -> Midwest | AB8: Northeast | AC8: 314 | AD8: Northeast | AE8: 314 | AF8: =$AF$4-AE8 -> 787.1 | AG8: =AD8&"("&AE8&")" -> Northeast(314) | AV8: Washington | AW8: 2978 | BF8: Ohio | BG8: 94 | BH8: 11900510 | BI8: =(Table24[[#This Row],[Dedicated Burn Beds]]/Table24[[#This Row],[Total population]])*100000 -> 0.78988211 | BJ8: =_xlfn.XLOOKUP(Table24[[#This Row],[State]],'[1]State Regions'!$A:$A,'[1]State Regions'!$B:$B) -> Midwest | BN8: Pennsylvania | BO8: 83 | BP8: 13059432
D9: Missouri | E9: 93 | F9: Missouri | G9: 93 | H9: =_xlfn.XLOOKUP(D9,'State Population (2026)'!B:B,'State Population (2026)'!C:C,0) -> 6270541 | R9: Alabama | S9: 52 | V9: Missouri | W9: 93 | X9: 6270541 | Y9: =(Table2[[#This Row],[Dedicated Burn Beds]]/Table2[[#This Row],[Total population]])*100000 -> 1.4831256 | Z9: =_xlfn.XLOOKUP(Table2[[#This Row],[State]],'[1]State Regions'!$A:$A,'[1]State Regions'!$B:$B) -> Midwest | AB9: Grand Total | AC9: 2080 | AV9: Utah | AW9: 2869 | BF9: Missouri | BG9: 93 | BH9: 6270541 | BI9: =(Table24[[#This Row],[Dedicated Burn Beds]]/Table24[[#This Row],[Total population]])*100000 -> 1.4831256 | BJ9: =_xlfn.XLOOKUP(Table24[[#This Row],[State]],'[1]State Regions'!$A:$A,'[1]State Regions'!$B:$B) -> Midwest | BN9: Illinois | BO9: 77 | BP9: 12719141
D10: Florida | E10: 85 | F10: Florida | G10: 85 | H10: =_xlfn.XLOOKUP(D10,'State Population (2026)'!B:B,'State Population (2026)'!C:C,0) -> 23462518 | R10: Tennessee | S10: 51 | V10: Florida | W10: 85 | X10: 23462518 | Y10: =(Table2[[#This Row],[Dedicated Burn Beds]]/Table2[[#This Row],[Total population]])*100000 -> 0.36227996 | Z10: =_xlfn.XLOOKUP(Table2[[#This Row],[State]],'[1]State Regions'!$A:$A,'[1]State Regions'!$B:$B) -> South | AV10: Oregon | AW10: 2768 | BF10: Florida | BG10: 85 | BH10: 23462518 | BI10: =(Table24[[#This Row],[Dedicated Burn Beds]]/Table24[[#This Row],[Total population]])*100000 -> 0.36227996 | BJ10: =_xlfn.XLOOKUP(Table24[[#This Row],[State]],'[1]State Regions'!$A:$A,'[1]State Regions'!$B:$B) -> South | BN10: Ohio | BO10: 94 | BP10: 11900510
D11: Pennsylvania | E11: 83 | F11: Pennsylvania | G11: 83 | H11: =_xlfn.XLOOKUP(D11,'State Population (2026)'!B:B,'State Population (2026)'!C:C,0) -> 13059432 | R11: Louisiana | S11: 47 | V11: Pennsylvania | W11: 83 | X11: 13059432 | Y11: =(Table2[[#This Row],[Dedicated Burn Beds]]/Table2[[#This Row],[Total population]])*100000 -> 0.63555597 | Z11: =_xlfn.XLOOKUP(Table2[[#This Row],[State]],'[1]State Regions'!$A:$A,'[1]State Regions'!$B:$B) -> Northeast | AV11: Nevada | AW11: 2073 | BF11: Pennsylvania | BG11: 83 | BH11: 13059432 | BI11: =(Table24[[#This Row],[Dedicated Burn Beds]]/Table24[[#This Row],[Total population]])*100000 -> 0.63555597 | BJ11: =_xlfn.XLOOKUP(Table24[[#This Row],[State]],'[1]State Regions'!$A:$A,'[1]State Regions'!$B:$B) -> Northeast | BN11: Georgia | BO11: 129 | BP11: 11302748
D12: Arizona | E12: 80 | F12: Arizona | G12: 80 | H12: =_xlfn.XLOOKUP(D12,'State Population (2026)'!B:B,'State Population (2026)'!C:C,0) -> 7623818 | R12: District of Columbia | S12: 41 | V12: Arizona | W12: 80 | X12: 7623818 | Y12: =(Table2[[#This Row],[Dedicated Burn Beds]]/Table2[[#This Row],[Total population]])*100000 -> 1.049343 | Z12: =_xlfn.XLOOKUP(Table2[[#This Row],[State]],'[1]State Regions'!$A:$A,'[1]State Regions'!$B:$B) -> West | AJ12: Percentage of Verified beds ABA | AM12: =GETPIVOTDATA("BURN_BEDS(beds dedicated to burn care)",$AI$4,"ABA_VERIFIED","Yes")/GETPIVOTDATA("BURN_BEDS(beds dedicated to burn care)",$AI$4) -> 0.53128689 | AV12: Idaho | AW12: 1471 | BF12: Arizona | BG12: 80 | BH12: 7623818 | BI12: =(Table24[[#This Row],[Dedicated Burn Beds]]/Table24[[#This Row],[Total population]])*100000 -> 1.049343 | BJ12: =_xlfn.XLOOKUP(Table24[[#This Row],[State]],'[1]State Regions'!$A:$A,'[1]State Regions'!$B:$B) -> West | BN12: North Carolina | BO12: 60 | BP12: 11197968
D13: Illinois | E13: 77 | F13: Illinois | G13: 77 | H13: =_xlfn.XLOOKUP(D13,'State Population (2026)'!B:B,'State Population (2026)'!C:C,0) -> 12719141 | R13: Oklahoma | S13: 33 | V13: Illinois | W13: 77 | X13: 12719141 | Y13: =(Table2[[#This Row],[Dedicated Burn Beds]]/Table2[[#This Row],[Total population]])*100000 -> 0.60538679 | Z13: =_xlfn.XLOOKUP(Table2[[#This Row],[State]],'[1]State Regions'!$A:$A,'[1]State Regions'!$B:$B) -> Midwest | AV13: Montana | AW13: 1357 | BF13: Illinois | BG13: 77 | BH13: 12719141 | BI13: =(Table24[[#This Row],[Dedicated Burn Beds]]/Table24[[#This Row],[Total population]])*100000 -> 0.60538679 | BJ13: =_xlfn.XLOOKUP(Table24[[#This Row],[State]],'[1]State Regions'!$A:$A,'[1]State Regions'!$B:$B) -> Midwest | BN13: Michigan | BO13: 69 | BP13: 10127884
A14: Row Labels | D14: Michigan | E14: 69 | F14: Michigan | G14: 69 | H14: =_xlfn.XLOOKUP(D14,'State Population (2026)'!B:B,'State Population (2026)'!C:C,0) -> 10127884 | R14: South Carolina | S14: 25 | V14: Michigan | W14: 69 | X14: 10127884 | Y14: =(Table2[[#This Row],[Dedicated Burn Beds]]/Table2[[#This Row],[Total population]])*100000 -> 0.68128742 | Z14: =_xlfn.XLOOKUP(Table2[[#This Row],[State]],'[1]State Regions'!$A:$A,'[1]State Regions'!$B:$B) -> Midwest | AV14: Hawaii | AW14: 1246 | BF14: Michigan | BG14: 69 | BH14: 10127884 | BI14: =(Table24[[#This Row],[Dedicated Burn Beds]]/Table24[[#This Row],[Total population]])*100000 -> 0.68128742 | BJ14: =_xlfn.XLOOKUP(Table24[[#This Row],[State]],'[1]State Regions'!$A:$A,'[1]State Regions'!$B:$B) -> Midwest | BN14: New Jersey | BO14: 12 | BP14: 9548215
A15: Alabama | D15: Virginia | E15: 68 | F15: Virginia | G15: 68 | H15: =_xlfn.XLOOKUP(D15,'State Population (2026)'!B:B,'State Population (2026)'!C:C,0) -> 8880107 | R15: Maryland | S15: 20 | V15: Virginia | W15: 68 | X15: 8880107 | Y15: =(Table2[[#This Row],[Dedicated Burn Beds]]/Table2[[#This Row],[Total population]])*100000 -> 0.76575654 | Z15: =_xlfn.XLOOKUP(Table2[[#This Row],[State]],'[1]State Regions'!$A:$A,'[1]State Regions'!$B:$B) -> South | AV15: Alaska | AW15: 574 | BF15: Virginia | BG15: 68 | BH15: 8880107 | BI15: =(Table24[[#This Row],[Dedicated Burn Beds]]/Table24[[#This Row],[Total population]])*100000 -> 0.76575654 | BJ15: =_xlfn.XLOOKUP(Table24[[#This Row],[State]],'[1]State Regions'!$A:$A,'[1]State Regions'!$B:$B) -> South | BN15: Virginia | BO15: 68 | BP15: 8880107
A16: Arkansas | D16: North Carolina | E16: 60 | F16: North Carolina | G16: 60 | H16: =_xlfn.XLOOKUP(D16,'State Population (2026)'!B:B,'State Population (2026)'!C:C,0) -> 11197968 | R16: Kentucky | S16: 16 | V16: North Carolina | W16: 60 | X16: 11197968 | Y16: =(Table2[[#This Row],[Dedicated Burn Beds]]/Table2[[#This Row],[Total population]])*100000 -> 0.5358115 | Z16: =_xlfn.XLOOKUP(Table2[[#This Row],[State]],'[1]State Regions'!$A:$A,'[1]State Regions'!$B:$B) -> South | AV16: New Mexico | AW16: 556 | BF16: North Carolina | BG16: 60 | BH16: 11197968 | BI16: =(Table24[[#This Row],[Dedicated Burn Beds]]/Table24[[#This Row],[Total population]])*100000 -> 0.5358115 | BJ16: =_xlfn.XLOOKUP(Table24[[#This Row],[State]],'[1]State Regions'!$A:$A,'[1]State Regions'!$B:$B) -> South | BN16: Washington | BO16: 40 | BP16: 8001020
A17: Delaware | D17: Alabama | E17: 52 | F17: Alabama | G17: 52 | H17: =_xlfn.XLOOKUP(D17,'State Population (2026)'!B:B,'State Population (2026)'!C:C,0) -> 5193088 | R17: Arkansas | S17: 10 | V17: Alabama | W17: 52 | X17: 5193088 | Y17: =(Table2[[#This Row],[Dedicated Burn Beds]]/Table2[[#This Row],[Total population]])*100000 -> 1.001331 | Z17: =_xlfn.XLOOKUP(Table2[[#This Row],[State]],'[1]State Regions'!$A:$A,'[1]State Regions'!$B:$B) -> South | AV17: Grand Total | AW17: 50886 | BF17: Alabama | BG17: 52 | BH17: 5193088 | BI17: =(Table24[[#This Row],[Dedicated Burn Beds]]/Table24[[#This Row],[Total population]])*100000 -> 1.001331 | BJ17: =_xlfn.XLOOKUP(Table24[[#This Row],[State]],'[1]State Regions'!$A:$A,'[1]State Regions'!$B:$B) -> South | BN17: Arizona | BO17: 80 | BP17: 7623818
A18: District of Columbia | D18: Colorado | E18: 52 | F18: Colorado | G18: 52 | H18: =_xlfn.XLOOKUP(D18,'State Population (2026)'!B:B,'State Population (2026)'!C:C,0) -> 6012561 | R18: West Virginia | S18: 4 | V18: Colorado | W18: 52 | X18: 6012561 | Y18: =(Table2[[#This Row],[Dedicated Burn Beds]]/Table2[[#This Row],[Total population]])*100000 -> 0.86485609 | Z18: =_xlfn.XLOOKUP(Table2[[#This Row],[State]],'[1]State Regions'!$A:$A,'[1]State Regions'!$B:$B) -> West | BF18: Colorado | BG18: 52 | BH18: 6012561 | BI18: =(Table24[[#This Row],[Dedicated Burn Beds]]/Table24[[#This Row],[Total population]])*100000 -> 0.86485609 | BJ18: =_xlfn.XLOOKUP(Table24[[#This Row],[State]],'[1]State Regions'!$A:$A,'[1]State Regions'!$B:$B) -> West | BN18: Tennessee | BO18: 51 | BP18: 7315076
A19: Florida | D19: Massachusetts | E19: 52 | F19: Massachusetts | G19: 52 | H19: =_xlfn.XLOOKUP(D19,'State Population (2026)'!B:B,'State Population (2026)'!C:C,0) -> 7154084 | R19: Mississippi | V19: Massachusetts | W19: 52 | X19: 7154084 | Y19: =(Table2[[#This Row],[Dedicated Burn Beds]]/Table2[[#This Row],[Total population]])*100000 -> 0.72685755 | Z19: =_xlfn.XLOOKUP(Table2[[#This Row],[State]],'[1]State Regions'!$A:$A,'[1]State Regions'!$B:$B) -> Northeast | BF19: Massachusetts | BG19: 52 | BH19: 7154084 | BI19: =(Table24[[#This Row],[Dedicated Burn Beds]]/Table24[[#This Row],[Total population]])*100000 -> 0.72685755 | BJ19: =_xlfn.XLOOKUP(Table24[[#This Row],[State]],'[1]State Regions'!$A:$A,'[1]State Regions'!$B:$B) -> Northeast | BN19: Massachusetts | BO19: 52 | BP19: 7154084
A20: Georgia | D20: Tennessee | E20: 51 | F20: Tennessee | G20: 51 | H20: =_xlfn.XLOOKUP(D20,'State Population (2026)'!B:B,'State Population (2026)'!C:C,0) -> 7315076 | R20: Delaware | V20: Tennessee | W20: 51 | X20: 7315076 | Y20: =(Table2[[#This Row],[Dedicated Burn Beds]]/Table2[[#This Row],[Total population]])*100000 -> 0.6971903 | Z20: =_xlfn.XLOOKUP(Table2[[#This Row],[State]],'[1]State Regions'!$A:$A,'[1]State Regions'!$B:$B) -> South | BF20: Tennessee | BG20: 51 | BH20: 7315076 | BI20: =(Table24[[#This Row],[Dedicated Burn Beds]]/Table24[[#This Row],[Total population]])*100000 -> 0.6971903 | BJ20: =_xlfn.XLOOKUP(Table24[[#This Row],[State]],'[1]State Regions'!$A:$A,'[1]State Regions'!$B:$B) -> South | BN20: Indiana | BO20: 41 | BP20: 6973333
A21: Kentucky | D21: Minnesota | E21: 50 | F21: Minnesota | G21: 50 | H21: =_xlfn.XLOOKUP(D21,'State Population (2026)'!B:B,'State Population (2026)'!C:C,0) -> 5830405 | R21: Grand Total | S21: 847 | V21: Minnesota | W21: 50 | X21: 5830405 | Y21: =(Table2[[#This Row],[Dedicated Burn Beds]]/Table2[[#This Row],[Total population]])*100000 -> 0.85757336 | Z21: =_xlfn.XLOOKUP(Table2[[#This Row],[State]],'[1]State Regions'!$A:$A,'[1]State Regions'!$B:$B) -> Midwest | BF21: Minnesota | BG21: 50 | BH21: 5830405 | BI21: =(Table24[[#This Row],[Dedicated Burn Beds]]/Table24[[#This Row],[Total population]])*100000 -> 0.85757336 | BJ21: =_xlfn.XLOOKUP(Table24[[#This Row],[State]],'[1]State Regions'!$A:$A,'[1]State Regions'!$B:$B) -> Midwest | BN21: Missouri | BO21: 93 | BP21: 6270541
A22: Louisiana | D22: Louisiana | E22: 47 | F22: Louisiana | G22: 47 | H22: =_xlfn.XLOOKUP(D22,'State Population (2026)'!B:B,'State Population (2026)'!C:C,0) -> 4618189 | V22: Louisiana | W22: 47 | X22: 4618189 | Y22: =(Table2[[#This Row],[Dedicated Burn Beds]]/Table2[[#This Row],[Total population]])*100000 -> 1.017715 | Z22: =_xlfn.XLOOKUP(Table2[[#This Row],[State]],'[1]State Regions'!$A:$A,'[1]State Regions'!$B:$B) -> South | BF22: Louisiana | BG22: 47 | BH22: 4618189 | BI22: =(Table24[[#This Row],[Dedicated Burn Beds]]/Table24[[#This Row],[Total population]])*100000 -> 1.017715 | BJ22: =_xlfn.XLOOKUP(Table24[[#This Row],[State]],'[1]State Regions'!$A:$A,'[1]State Regions'!$B:$B) -> South | BN22: Maryland | BO22: 20 | BP22: 6265347
A23: Maryland | D23: Indiana | E23: 41 | F23: Indiana | G23: 41 | H23: =_xlfn.XLOOKUP(D23,'State Population (2026)'!B:B,'State Population (2026)'!C:C,0) -> 6973333 | V23: Indiana | W23: 41 | X23: 6973333 | Y23: =(Table2[[#This Row],[Dedicated Burn Beds]]/Table2[[#This Row],[Total population]])*100000 -> 0.58795414 | Z23: =_xlfn.XLOOKUP(Table2[[#This Row],[State]],'[1]State Regions'!$A:$A,'[1]State Regions'!$B:$B) -> Midwest | BF23: Indiana | BG23: 41 | BH23: 6973333 | BI23: =(Table24[[#This Row],[Dedicated Burn Beds]]/Table24[[#This Row],[Total population]])*100000 -> 0.58795414 | BJ23: =_xlfn.XLOOKUP(Table24[[#This Row],[State]],'[1]State Regions'!$A:$A,'[1]State Regions'!$B:$B) -> Midwest | BN23: Colorado | BO23: 52 | BP23: 6012561
A24: Mississippi | D24: District of Columbia | E24: 41 | F24: District of Columbia | G24: 41 | H24: =_xlfn.XLOOKUP(D24,'State Population (2026)'!B:B,'State Population (2026)'!C:C,0) -> 693645 | V24: District of Columbia | W24: 41 | X24: 693645 | Y24: =(Table2[[#This Row],[Dedicated Burn Beds]]/Table2[[#This Row],[Total population]])*100000 -> 5.9108045 | Z24: =_xlfn.XLOOKUP(Table2[[#This Row],[State]],'[1]State Regions'!$A:$A,'[1]State Regions'!$B:$B) -> South | BF24: District of Columbia | BG24: 41 | BH24: 693645 | BI24: =(Table24[[#This Row],[Dedicated Burn Beds]]/Table24[[#This Row],[Total population]])*100000 -> 5.9108045 | BJ24: =_xlfn.XLOOKUP(Table24[[#This Row],[State]],'[1]State Regions'!$A:$A,'[1]State Regions'!$B:$B) -> South | BN24: Wisconsin | BO24: 28 | BP24: 5972787
A25: North Carolina | D25: Washington | E25: 40 | F25: Washington | G25: 40 | H25: =_xlfn.XLOOKUP(D25,'State Population (2026)'!B:B,'State Population (2026)'!C:C,0) -> 8001020 | V25: Washington | W25: 40 | X25: 8001020 | Y25: =(Table2[[#This Row],[Dedicated Burn Beds]]/Table2[[#This Row],[Total population]])*100000 -> 0.49993626 | Z25: =_xlfn.XLOOKUP(Table2[[#This Row],[State]],'[1]State Regions'!$A:$A,'[1]State Regions'!$B:$B) -> West | BF25: Washington | BG25: 40 | BH25: 8001020 | BI25: =(Table24[[#This Row],[Dedicated Burn Beds]]/Table24[[#This Row],[Total population]])*100000 -> 0.49993626 | BJ25: =_xlfn.XLOOKUP(Table24[[#This Row],[State]],'[1]State Regions'!$A:$A,'[1]State Regions'!$B:$B) -> West | BN25: Minnesota | BO25: 50 | BP25: 5830405
A26: Oklahoma | D26: Oklahoma | E26: 33 | F26: Oklahoma | G26: 33 | H26: =_xlfn.XLOOKUP(D26,'State Population (2026)'!B:B,'State Population (2026)'!C:C,0) -> 4123288 | V26: Oklahoma | W26: 33 | X26: 4123288 | Y26: =(Table2[[#This Row],[Dedicated Burn Beds]]/Table2[[#This Row],[Total population]])*100000 -> 0.80033216 | Z26: =_xlfn.XLOOKUP(Table2[[#This Row],[State]],'[1]State Regions'!$A:$A,'[1]State Regions'!$B:$B) -> South | BF26: Oklahoma | BG26: 33 | BH26: 4123288 | BI26: =(Table24[[#This Row],[Dedicated Burn Beds]]/Table24[[#This Row],[Total population]])*100000 -> 0.80033216 | BJ26: =_xlfn.XLOOKUP(Table24[[#This Row],[State]],'[1]State Regions'!$A:$A,'[1]State Regions'!$B:$B) -> South | BN26: South Carolina | BO26: 25 | BP26: 5570274
A27: South Carolina | D27: Nevada | E27: 31 | F27: Nevada | G27: 31 | H27: =_xlfn.XLOOKUP(D27,'State Population (2026)'!B:B,'State Population (2026)'!C:C,0) -> 3282188 | V27: Nevada | W27: 31 | X27: 3282188 | Y27: =(Table2[[#This Row],[Dedicated Burn Beds]]/Table2[[#This Row],[Total population]])*100000 -> 0.94449191 | Z27: =_xlfn.XLOOKUP(Table2[[#This Row],[State]],'[1]State Regions'!$A:$A,'[1]State Regions'!$B:$B) -> West | BF27: Nevada | BG27: 31 | BH27: 3282188 | BI27: =(Table24[[#This Row],[Dedicated Burn Beds]]/Table24[[#This Row],[Total population]])*100000 -> 0.94449191 | BJ27: =_xlfn.XLOOKUP(Table24[[#This Row],[State]],'[1]State Regions'!$A:$A,'[1]State Regions'!$B:$B) -> West | BN27: Alabama | BO27: 52 | BP27: 5193088
A28: Tennessee | D28: Wisconsin | E28: 28 | F28: Wisconsin | G28: 28 | H28: =_xlfn.XLOOKUP(D28,'State Population (2026)'!B:B,'State Population (2026)'!C:C,0) -> 5972787 | V28: Wisconsin | W28: 28 | X28: 5972787 | Y28: =(Table2[[#This Row],[Dedicated Burn Beds]]/Table2[[#This Row],[Total population]])*100000 -> 0.46879288 | Z28: =_xlfn.XLOOKUP(Table2[[#This Row],[State]],'[1]State Regions'!$A:$A,'[1]State Regions'!$B:$B) -> Midwest | BF28: Wisconsin | BG28: 28 | BH28: 5972787 | BI28: =(Table24[[#This Row],[Dedicated Burn Beds]]/Table24[[#This Row],[Total population]])*100000 -> 0.46879288 | BJ28: =_xlfn.XLOOKUP(Table24[[#This Row],[State]],'[1]State Regions'!$A:$A,'[1]State Regions'!$B:$B) -> Midwest | BN28: Louisiana | BO28: 47 | BP28: 4618189
A29: Texas | D29: Kansas | E29: 28 | F29: Kansas | G29: 28 | H29: =_xlfn.XLOOKUP(D29,'State Population (2026)'!B:B,'State Population (2026)'!C:C,0) -> 2977220 | V29: Kansas | W29: 28 | X29: 2977220 | Y29: =(Table2[[#This Row],[Dedicated Burn Beds]]/Table2[[#This Row],[Total population]])*100000 -> 0.94047467 | Z29: =_xlfn.XLOOKUP(Table2[[#This Row],[State]],'[1]State Regions'!$A:$A,'[1]State Regions'!$B:$B) -> Midwest | BF29: Kansas | BG29: 28 | BH29: 2977220 | BI29: =(Table24[[#This Row],[Dedicated Burn Beds]]/Table24[[#This Row],[Total population]])*100000 -> 0.94047467 | BJ29: =_xlfn.XLOOKUP(Table24[[#This Row],[State]],'[1]State Regions'!$A:$A,'[1]State Regions'!$B:$B) -> Midwest | BN29: Kentucky | BO29: 16 | BP29: 4606864
A30: Virginia | D30: South Carolina | E30: 25 | F30: South Carolina | G30: 25 | H30: =_xlfn.XLOOKUP(D30,'State Population (2026)'!B:B,'State Population (2026)'!C:C,0) -> 5570274 | V30: South Carolina | W30: 25 | X30: 5570274 | Y30: =(Table2[[#This Row],[Dedicated Burn Beds]]/Table2[[#This Row],[Total population]])*100000 -> 0.44881096 | Z30: =_xlfn.XLOOKUP(Table2[[#This Row],[State]],'[1]State Regions'!$A:$A,'[1]State Regions'!$B:$B) -> South | BF30: South Carolina | BG30: 25 | BH30: 5570274 | BI30: =(Table24[[#This Row],[Dedicated Burn Beds]]/Table24[[#This Row],[Total population]])*100000 -> 0.44881096 | BJ30: =_xlfn.XLOOKUP(Table24[[#This Row],[State]],'[1]State Regions'!$A:$A,'[1]State Regions'!$B:$B) -> South | BN30: Oregon | BO30: 16 | BP30: 4273586
A31: West Virginia | D31: Maryland | E31: 20 | F31: Maryland | G31: 20 | H31: =_xlfn.XLOOKUP(D31,'State Population (2026)'!B:B,'State Population (2026)'!C:C,0) -> 6265347 | V31: Maryland | W31: 20 | X31: 6265347 | Y31: =(Table2[[#This Row],[Dedicated Burn Beds]]/Table2[[#This Row],[Total population]])*100000 -> 0.31921616 | Z31: =_xlfn.XLOOKUP(Table2[[#This Row],[State]],'[1]State Regions'!$A:$A,'[1]State Regions'!$B:$B) -> South | BF31: Maryland | BG31: 20 | BH31: 6265347 | BI31: =(Table24[[#This Row],[Dedicated Burn Beds]]/Table24[[#This Row],[Total population]])*100000 -> 0.31921616 | BJ31: =_xlfn.XLOOKUP(Table24[[#This Row],[State]],'[1]State Regions'!$A:$A,'[1]State Regions'!$B:$B) -> South | BN31: Oklahoma | BO31: 33 | BP31: 4123288
A32: Grand Total | D32: Iowa | E32: 17 | F32: Iowa | G32: 17 | H32: =_xlfn.XLOOKUP(D32,'State Population (2026)'!B:B,'State Population (2026)'!C:C,0) -> 3238387 | V32: Iowa | W32: 17 | X32: 3238387 | Y32: =(Table2[[#This Row],[Dedicated Burn Beds]]/Table2[[#This Row],[Total population]])*100000 -> 0.5249527 | Z32: =_xlfn.XLOOKUP(Table2[[#This Row],[State]],'[1]State Regions'!$A:$A,'[1]State Regions'!$B:$B) -> Midwest | AO32: Trauma report 2022: Summary of 2021 Data | BF32: Iowa | BG32: 17 | BH32: 3238387 | BI32: =(Table24[[#This Row],[Dedicated Burn Beds]]/Table24[[#This Row],[Total population]])*100000 -> 0.5249527 | BJ32: =_xlfn.XLOOKUP(Table24[[#This Row],[State]],'[1]State Regions'!$A:$A,'[1]State Regions'!$B:$B) -> Midwest | BN32: Connecticut | BO32: 9 | BP32: 3688496
D33: Nebraska | E33: 16 | F33: Nebraska | G33: 16 | H33: =_xlfn.XLOOKUP(D33,'State Population (2026)'!B:B,'State Population (2026)'!C:C,0) -> 2018006 | V33: Nebraska | W33: 16 | X33: 2018006 | Y33: =(Table2[[#This Row],[Dedicated Burn Beds]]/Table2[[#This Row],[Total population]])*100000 -> 0.79286186 | Z33: =_xlfn.XLOOKUP(Table2[[#This Row],[State]],'[1]State Regions'!$A:$A,'[1]State Regions'!$B:$B) -> Midwest | AO33: Source: Montana Trauma Registry Annual Report 2022 | BF33: Nebraska | BG33: 16 | BH33: 2018006 | BI33: =(Table24[[#This Row],[Dedicated Burn Beds]]/Table24[[#This Row],[Total population]])*100000 -> 0.79286186 | BJ33: =_xlfn.XLOOKUP(Table24[[#This Row],[State]],'[1]State Regions'!$A:$A,'[1]State Regions'!$B:$B) -> Midwest | BN33: Utah | BO33: 15 | BP33: 3538904
D34: Kentucky | E34: 16 | F34: Kentucky | G34: 16 | H34: =_xlfn.XLOOKUP(D34,'State Population (2026)'!B:B,'State Population (2026)'!C:C,0) -> 4606864 | V34: Kentucky | W34: 16 | X34: 4606864 | Y34: =(Table2[[#This Row],[Dedicated Burn Beds]]/Table2[[#This Row],[Total population]])*100000 -> 0.34730784 | Z34: =_xlfn.XLOOKUP(Table2[[#This Row],[State]],'[1]State Regions'!$A:$A,'[1]State Regions'!$B:$B) -> South | BF34: Kentucky | BG34: 16 | BH34: 4606864 | BI34: =(Table24[[#This Row],[Dedicated Burn Beds]]/Table24[[#This Row],[Total population]])*100000 -> 0.34730784 | BJ34: =_xlfn.XLOOKUP(Table24[[#This Row],[State]],'[1]State Regions'!$A:$A,'[1]State Regions'!$B:$B) -> South | BN34: Nevada | BO34: 31 | BP34: 3282188
D35: Oregon | E35: 16 | F35: Oregon | G35: 16 | H35: =_xlfn.XLOOKUP(D35,'State Population (2026)'!B:B,'State Population (2026)'!C:C,0) -> 4273586 | V35: Oregon | W35: 16 | X35: 4273586 | Y35: =(Table2[[#This Row],[Dedicated Burn Beds]]/Table2[[#This Row],[Total population]])*100000 -> 0.37439284 | Z35: =_xlfn.XLOOKUP(Table2[[#This Row],[State]],'[1]State Regions'!$A:$A,'[1]State Regions'!$B:$B) -> West | BF35: Oregon | BG35: 16 | BH35: 4273586 | BI35: =(Table24[[#This Row],[Dedicated Burn Beds]]/Table24[[#This Row],[Total population]])*100000 -> 0.37439284 | BJ35: =_xlfn.XLOOKUP(Table24[[#This Row],[State]],'[1]State Regions'!$A:$A,'[1]State Regions'!$B:$B) -> West | BN35: Iowa | BO35: 17 | BP35: 3238387
D36: Idaho | E36: 15 | F36: Idaho | G36: 15 | H36: =_xlfn.XLOOKUP(D36,'State Population (2026)'!B:B,'State Population (2026)'!C:C,0) -> 2029733 | V36: Idaho | W36: 15 | X36: 2029733 | Y36: =(Table2[[#This Row],[Dedicated Burn Beds]]/Table2[[#This Row],[Total population]])*100000 -> 0.73901346 | Z36: =_xlfn.XLOOKUP(Table2[[#This Row],[State]],'[1]State Regions'!$A:$A,'[1]State Regions'!$B:$B) -> West | BF36: Idaho | BG36: 15 | BH36: 2029733 | BI36: =(Table24[[#This Row],[Dedicated Burn Beds]]/Table24[[#This Row],[Total population]])*100000 -> 0.73901346 | BJ36: =_xlfn.XLOOKUP(Table24[[#This Row],[State]],'[1]State Regions'!$A:$A,'[1]State Regions'!$B:$B) -> West | BN36: Arkansas | BO36: 10 | BP36: 3114791
D37: Utah | E37: 15 | F37: Utah | G37: 15 | H37: =_xlfn.XLOOKUP(D37,'State Population (2026)'!B:B,'State Population (2026)'!C:C,0) -> 3538904 | V37: Utah | W37: 15 | X37: 3538904 | Y37: =(Table2[[#This Row],[Dedicated Burn Beds]]/Table2[[#This Row],[Total population]])*100000 -> 0.42386004 | Z37: =_xlfn.XLOOKUP(Table2[[#This Row],[State]],'[1]State Regions'!$A:$A,'[1]State Regions'!$B:$B) -> West | BF37: Utah | BG37: 15 | BH37: 3538904 | BI37: =(Table24[[#This Row],[Dedicated Burn Beds]]/Table24[[#This Row],[Total population]])*100000 -> 0.42386004 | BJ37: =_xlfn.XLOOKUP(Table24[[#This Row],[State]],'[1]State Regions'!$A:$A,'[1]State Regions'!$B:$B) -> West | BN37: Kansas | BO37: 28 | BP37: 2977220
D38: New Jersey | E38: 12 | F38: New Jersey | G38: 12 | H38: =_xlfn.XLOOKUP(D38,'State Population (2026)'!B:B,'State Population (2026)'!C:C,0) -> 9548215 | V38: New Jersey | W38: 12 | X38: 9548215 | Y38: =(Table2[[#This Row],[Dedicated Burn Beds]]/Table2[[#This Row],[Total population]])*100000 -> 0.12567794 | Z38: =_xlfn.XLOOKUP(Table2[[#This Row],[State]],'[1]State Regions'!$A:$A,'[1]State Regions'!$B:$B) -> Northeast | BF38: New Jersey | BG38: 12 | BH38: 9548215 | BI38: =(Table24[[#This Row],[Dedicated Burn Beds]]/Table24[[#This Row],[Total population]])*100000 -> 0.12567794 | BJ38: =_xlfn.XLOOKUP(Table24[[#This Row],[State]],'[1]State Regions'!$A:$A,'[1]State Regions'!$B:$B) -> Northeast | BN38: Mississippi | BO38: 0 | BP38: 2954160
D39: New Mexico | E39: 10 | F39: New Mexico | G39: 10 | H39: =_xlfn.XLOOKUP(D39,'State Population (2026)'!B:B,'State Population (2026)'!C:C,0) -> 2125498 | V39: New Mexico | W39: 10 | X39: 2125498 | Y39: =(Table2[[#This Row],[Dedicated Burn Beds]]/Table2[[#This Row],[Total population]])*100000 -> 0.47047798 | Z39: =_xlfn.XLOOKUP(Table2[[#This Row],[State]],'[1]State Regions'!$A:$A,'[1]State Regions'!$B:$B) -> West | BF39: New Mexico | BG39: 10 | BH39: 2125498 | BI39: =(Table24[[#This Row],[Dedicated Burn Beds]]/Table24[[#This Row],[Total population]])*100000 -> 0.47047798 | BJ39: =_xlfn.XLOOKUP(Table24[[#This Row],[State]],'[1]State Regions'!$A:$A,'[1]State Regions'!$B:$B) -> West | BN39: New Mexico | BO39: 10 | BP39: 2125498
D40: Arkansas | E40: 10 | F40: Arkansas | G40: 10 | H40: =_xlfn.XLOOKUP(D40,'State Population (2026)'!B:B,'State Population (2026)'!C:C,0) -> 3114791 | V40: Arkansas | W40: 10 | X40: 3114791 | Y40: =(Table2[[#This Row],[Dedicated Burn Beds]]/Table2[[#This Row],[Total population]])*100000 -> 0.32104883 | Z40: =_xlfn.XLOOKUP(Table2[[#This Row],[State]],'[1]State Regions'!$A:$A,'[1]State Regions'!$B:$B) -> South | BF40: Arkansas | BG40: 10 | BH40: 3114791 | BI40: =(Table24[[#This Row],[Dedicated Burn Beds]]/Table24[[#This Row],[Total population]])*100000 -> 0.32104883 | BJ40: =_xlfn.XLOOKUP(Table24[[#This Row],[State]],'[1]State Regions'!$A:$A,'[1]State Regions'!$B:$B) -> South | BN40: Idaho | BO40: 15 | BP40: 2029733
...

Sheet Data Dictionary
A1: National Injury Resource Database (NIRD)
A3: Field Name | B3: Definition | C3: Value
A4: STATE_FULL | B4: Full spelling of the Hospital's state
A5: STATE | B5: 2 letter abbreviation of the Hospital's state
A6: COUNTY | B6: Hospital county
A7: ADDRESS | B7: Hospital street level address
A8: CITY | B8: Hospital city
A9: ZIP_CODE | B9: Hosptial 5-digit zip code
A10: AHA_ID | B10: Hospital American Hospital Association Identified
A11: HOSPITAL_NAME | B11: Hospital Name
A12: TOTAL_BEDS | B12: Total number of staffed beds - Reported from hospital websites, SDH documents, and/or AHA Guide Hospital Quick Search when available. If bed count was unreported across these sources, the hospital was contacted by an investigator.
A13: BURN_BEDS | B13: Number of beds dedicated to burn care - Reported from hospital websites, SDH burn center lists, 2012 ABA Burn Center Directory List, and/or by contacting burn center via phone.
A14: TRAUMA_ADULT | B14: 1 if either ADULT_TRAUMA_L1 or ADULT_TRAUMA_L2 are 1. ACS verified and/or state designated Adult Trauma Center, Level 1 or Level 2 – Reported from the ACS COT Hospitals and Facilities List, state department of health, and/or institution website. If adult capabilities were not reported online, the institution was contacted by an investigator. | C14: 1 or blank
A15: TRAUMA_PEDS | B15: 1 if PEDS_TRAUMA_L1 or PEDS_TRAUMA_L2 are 1. ACS verified and/or state designated Pediatric Trauma Center, Level 1 or Level 2 – Reported from the ACS COT Hospitals and Facilities List, state department of health, and/or institution website. If pediatric capabilities were not reported online, the institution was contacted by an investigator. | C15: 1 or blank
A16: BURN_ADULT | B16: 1 if ABA Verified, ABA non-verified, and/or state designated Adult Burn Center – Reported from the ABA Burn Center Directory, state department of health, and/or burn center website. | C16: 1 or blank
A17: BURN_PEDS | B17: 1 if ABA Verified, ABA non-verified, and/or state designated Adult Pediatric Burn Center – Reported from the ABA Burn Center Directory, state department of health, and/or burn center website. | C17: 1 or blank
A18: ACS_VERIFIED | B18: Trauma Centers - Verified by the ACS COT, Level 1 or Level 2. Note: These institutions can also be designated by SDH. | C18: Yes or No
A19: ADULT_TRAUMA_L1 | B19: Adult Level 1 Trauma Center Designated by American College of Surgeons and/or SDH. | C19: 1 or blank
A20: ADULT_TRAUMA_L2 | B20: Adult Level 2 Trauma Center Designated by American College of Surgeons and/or SDH | C20: 1 or blank
A21: PEDS_TRAUMA_L1 | B21: Pediatric Level 1 Trauma Center Designated by American College of Surgeons and/or SDH | C21: 1 or blank
A22: PEDS_TRAUMA_L2 | B22: Pediatric Level 2 Trauma Center Designated by American College of Surgeons and/or SDH | C22: 1 or blank
A23: ABA_VERIFIED | B23: Burn Centers - Verified by the ABA. Note: These institutions can also be designated or recognized by the state. | C23: Yes or No or blank
A24: TC_STATE_DESIGNATED | B24: TC Designated by the SDH, Level 1 or Level 2. Note: These institutions may also be verified by the ACS COT. | C24: Yes or No or blank
A25: BC_STATE_DESIGNATED | B25: BC Designated or Recognized by the SDH. Note: These institutions may also be recognized by the ABA. | C25: Yes or No or blank
A26: PHONE | B26: Main hospital phone number reported from hospital websites
A28: *Note: Each institution is either ABA/ACS Verified, State Designated, or Both
A29: *Note: If a TC was only designated by the state, TC level was reported from the SDH. In cases where TC were ACS COT V AND State D and TC Level varied between the two, ACS level was reported and a note was made under the institution.
A31: SDH = State Department of Health
A32: TC = Trauma Center

Sheet Data Table NIRD_irene
A1: STATE_FULL | B1: STATE | C1: COUNTY | D1: ADDRESS | E1: CITY | F1: ZIP_CODE | G1: AHA_ID(American Hospital Association Identifier) | H1: HOSPITAL_NAME | I1: TOTAL_BEDS(Total staffed hospital beds) | J1: BURN_BEDS(beds dedicated to burn care) | K1: TRAUMA_ADULT | L1: TRAUMA_PEDS | M1: BURN_ADULT | N1: BURN_PEDS | O1: ACS_VERIFIED | P1: ADULT_TRAUMA_L1 | Q1: ADULT_TRAUMA_L2 | R1: PEDS_TRAUMA_L1 | S1: PEDS_TRAUMA_L2 | T1: ABA_VERIFIED | U1: TC_STATE_DESIGNATED | V1: BC_STATE_DESIGNATED | W1: PHONE | X1: region
A2: Alaska | B2: AK | C2: Anchorage | D2: 4315 Diplomacy Dr | E2: Anchorage | F2: 99508 | G2: 6940010 | H2: Alaska Native Medical Center | I2: 173 | K2: 1 | L2: 1 | O2: Yes | Q2: 1 | S2: 1 | T2: No data | U2: Yes | W2: (907) 563-2662 | X2: =_xlfn.XLOOKUP(Burndata[[#This Row],[STATE_FULL]],'[1]State Regions'!$A:$A,'[1]State Regions'!$B:$B) -> West
A3: Alaska | B3: AK | C3: Anchorage | D3: 3200 Providence Dr | E3: Anchorage | F3: 99508 | G3: 6940020 | H3: Providence Alaska Medical Center/Children's Hospital at Providence | I3: 401 | K3: 1 | L3: 1 | O3: Yes | Q3: 1 | S3: 1 | T3: No data | U3: Yes | W3: (907) 562-2211 | X3: =_xlfn.XLOOKUP(Burndata[[#This Row],[STATE_FULL]],'[1]State Regions'!$A:$A,'[1]State Regions'!$B:$B) -> West
A4: Alabama | B4: AL | C4: Houston | D4: 1108 Ross Clark Cir | E4: Dothan | F4: 36301 | G4: 6530373 | H4: Southeast Alabama Medical Center | I4: 387 | K4: 1 | O4: No | Q4: 1 | T4: No data | U4: Yes | W4: (334) 793-8111 | X4: =_xlfn.XLOOKUP(Burndata[[#This Row],[STATE_FULL]],'[1]State Regions'!$A:$A,'[1]State Regions'!$B:$B) -> South
A5: Alabama | B5: AL | C5: Jefferson | D5: 619 19th St S | E5: Birmingham | F5: 35233 | G5: 6530304 | H5: University of Alabama at Birmingham Hospital (UAB Burn Center) | I5: 1157 | J5: 28 | K5: 1 | M5: 1 | O5: Yes | P5: 1 | T5: No | U5: Yes | V5: No | W5: (205) 934-3411 | X5: =_xlfn.XLOOKUP(Burndata[[#This Row],[STATE_FULL]],'[1]State Regions'!$A:$A,'[1]State Regions'!$B:$B) -> South
A6: Alabama | B6: AL | C6: Jefferson | D6: 1600 7th Ave South | E6: Birmingham | F6: 35233 | G6: 6530170 | H6: Children's of Alabama (Children's of Alabama Burn Center) | I6: 351 | J6: 6 | L6: 1 | N6: 1 | O6: No | R6: 1 | T6: No | U6: Yes | V6: No | W6: (205) 638-9100 | X6: =_xlfn.XLOOKUP(Burndata[[#This Row],[STATE_FULL]],'[1]State Regions'!$A:$A,'[1]State Regions'!$B:$B) -> South
A7: Alabama | B7: AL | C7: Madison | D7: 101 Sivley Rd | E7: Huntsville | F7: 35801 | G7: 6530510 | H7: Huntsville Hospital | I7: 958 | K7: 1 | O7: No | P7: 1 | T7: No data | U7: Yes | W7: (256) 265-1000 | X7: =_xlfn.XLOOKUP(Burndata[[#This Row],[STATE_FULL]],'[1]State Regions'!$A:$A,'[1]State Regions'!$B:$B) -> South
A8: Alabama | B8: AL | C8: Mobile | D8: 2451 University Hospital Dr | E8: Mobile | F8: 36617 | G8: 6530600 | H8: USA Health University Hospital (Arnold Luterman Regional Burn Center) | I8: 214 | J8: 18 | K8: 1 | M8: 1 | O8: No | P8: 1 | T8: No | U8: Yes | V8: No | W8: (251) 471-7000 | X8: =_xlfn.XLOOKUP(Burndata[[#This Row],[STATE_FULL]],'[1]State Regions'!$A:$A,'[1]State Regions'!$B:$B) -> South
A9: Alabama | B9: AL | C9: Montgomery | D9: 2105 E South Blvd | E9: Montgomery | F9: 36116 | G9: 6530705 | H9: Baptist Medical Center South | I9: 492 | K9: 1 | O9: No | Q9: 1 | T9: No data | U9: Yes | W9: (334) 288-2100 | X9: =_xlfn.XLOOKUP(Burndata[[#This Row],[STATE_FULL]],'[1]State Regions'!$A:$A,'[1]State Regions'!$B:$B) -> South
A10: Arizona | B10: AZ | C10: Coconino | D10: 1200 N Beaver St | E10: Flagstaff | F10: 86001 | G10: 6860021 | H10: Flagstaff Medical Center | I10: 268 | K10: 1 | O10: Yes | Q10: 1 | T10: No data | U10: Yes | W10: (928) 779-3366 | X10: =_xlfn.XLOOKUP(Burndata[[#This Row],[STATE_FULL]],'[1]State Regions'!$A:$A,'[1]State Regions'!$B:$B) -> West
A11: Arizona | B11: AZ | C11: Maricopa | D11: 1955 W Frye Rd | E11: Chandler | F11: 85224 | G11: 6860028 | H11: Chandler Regional Medical Center | I11: 338 | K11: 1 | O11: Yes | P11: 1 | T11: No data | U11: Yes | W11: (480) 728-3000 | X11: =_xlfn.XLOOKUP(Burndata[[#This Row],[STATE_FULL]],'[1]State Regions'!$A:$A,'[1]State Regions'!$B:$B) -> West
A12: Arizona | B12: AZ | C12: Maricopa | D12: 5555 W Thunderbird Rd | E12: Glendale | F12: 85306 | G12: 6860013 | H12: Banner Thunderbird Medical Center | I12: 595 | K12: 1 | O12: Yes | Q12: 1 | T12: No data | U12: Yes | W12: (602) 865-5555 | X12: =_xlfn.XLOOKUP(Burndata[[#This Row],[STATE_FULL]],'[1]State Regions'!$A:$A,'[1]State Regions'!$B:$B) -> West
A13: Arizona | B13: AZ | C13: Maricopa | D13: 13677 W McDowell Rd | E13: Goodyear | F13: 85395 | G13: 6860027 | H13: Abrazo West Campus | I13: 188 | K13: 1 | O13: Yes | Q13: 1 | T13: No data | U13: Yes | W13: (623) 882-1500 | X13: =_xlfn.XLOOKUP(Burndata[[#This Row],[STATE_FULL]],'[1]State Regions'!$A:$A,'[1]State Regions'!$B:$B) -> West
A14: Arizona | B14: AZ | C14: Maricopa | D14: 1400 S Dobson Rd | E14: Mesa | F14: 85202 | G14: 6860016 | H14: Banner Desert Medical Center/Banner Children's at Desert | I14: 605 | K14: 1 | L14: 1 | O14: Yes | Q14: 1 | S14: 1 | T14: No data | U14: Yes | W14: (480) 412-3000 | X14: =_xlfn.XLOOKUP(Burndata[[#This Row],[STATE_FULL]],'[1]State Regions'!$A:$A,'[1]State Regions'!$B:$B) -> West
A15: Arizona | B15: AZ | C15: Maricopa | D15: 1111 E McDowell Rd | E15: Phoenix | F15: 85006 | G15: 6860250 | H15: Banner University Medical Center - Phoenix | I15: 698 | K15: 1 | O15: Yes | P15: 1 | T15: No data | U15: Yes | W15: (602) 239-2000 | X15: =_xlfn.XLOOKUP(Burndata[[#This Row],[STATE_FULL]],'[1]State Regions'!$A:$A,'[1]State Regions'!$B:$B) -> West
A16: Arizona | B16: AZ | C16: Maricopa | D16: 350 W Thomas Rd | E16: Phoenix | F16: 85013 | G16: 6860280 | H16: St. Joseph's Hospital and Medical Center | I16: 594 | K16: 1 | O16: Yes | P16: 1 | T16: No data | U16: Yes | W16: (602) 406-3000 | X16: =_xlfn.XLOOKUP(Burndata[[#This Row],[STATE_FULL]],'[1]State Regions'!$A:$A,'[1]State Regions'!$B:$B) -> West
A17: Arizona | B17: AZ | C17: Maricopa | D17: 19829 North 27th Ave | E17: Phoenix | F17: 85027 | G17: 6860325 | H17: HonorHealth Deer Valley Medical Center | I17: 204 | K17: 1 | O17: Yes | Q17: 1 | T17: No data | U17: Yes | W17: (623) 879-6100 | X17: =_xlfn.XLOOKUP(Burndata[[#This Row],[STATE_FULL]],'[1]State Regions'!$A:$A,'[1]State Regions'!$B:$B) -> West
A18: Arizona | B18: AZ | C18: Maricopa | D18: 250 E Dunlap Ave | E18: Phoenix | F18: 85020 | G18: 6860253 | H18: HonorHealth John C. Lincoln Medical Center | I18: 262 | K18: 1 | O18: Yes | P18: 1 | T18: No data | U18: Yes | W18: (602) 943-2381 | X18: =_xlfn.XLOOKUP(Burndata[[#This Row],[STATE_FULL]],'[1]State Regions'!$A:$A,'[1]State Regions'!$B:$B) -> West
A19: Arizona | B19: AZ | C19: Maricopa | D19: 1919 E Thomas Rd | E19: Phoenix | F19: 85016 | G19: 6860210 | H19: Phoenix Children's Hospital | I19: 403 | L19: 1 | O19: Yes | R19: 1 | T19: No data | U19: Yes | W19: (602) 933-1000 | X19: =_xlfn.XLOOKUP(Burndata[[#This Row],[STATE_FULL]],'[1]State Regions'!$A:$A,'[1]State Regions'!$B:$B) -> West
A20: Arizona | B20: AZ | C20: Maricopa | D20: 2601 E Roosevelt St | E20: Phoenix | F20: 85008 | G20: 6860255 | H20: Valleywise Health (Arizona Burn Center) | I20: 544 | J20: 45 | K20: 1 | M20: 1 | N20: 1 | O20: Yes | P20: 1 | T20: Yes | U20: Yes | V20: No | W20: (602) 344-5011 | X20: =_xlfn.XLOOKUP(Burndata[[#This Row],[STATE_FULL]],'[1]State Regions'!$A:$A,'[1]State Regions'!$B:$B) -> West
A21: Arizona | B21: AZ | C21: Maricopa | D21: 7400 E Osborn Rd | E21: Scottsdale | F21: 85251 | G21: 6860376 | H21: HonorHealth Scottsdale Osborn Medical Center | I21: 341 | K21: 1 | O21: Yes | P21: 1 | T21: No data | U21: Yes | W21: (480) 882-4000 | X21: =_xlfn.XLOOKUP(Burndata[[#This Row],[STATE_FULL]],'[1]State Regions'!$A:$A,'[1]State Regions'!$B:$B) -> West
A22: Arizona | B22: AZ | C22: Pima | D22: 1501 N Campbell Ave | E22: Tucson | F22: 85719 | G22: 6860516 | H22: Banner University Medical Center - Tucson (Burn Unit at Banner) | I22: 584 | J22: 35 | K22: 1 | L22: 1 | M22: 1 | N22: 1 | O22: Yes | P22: 1 | S22: 1 | T22: No | U22: Yes | V22: No | W22: (520) 694-0111 | X22: =_xlfn.XLOOKUP(Burndata[[#This Row],[STATE_FULL]],'[1]State Regions'!$A:$A,'[1]State Regions'!$B:$B) -> West
A23: Arizona | B23: AZ | C23: Pima | D23: 350 N Wilmot Rd | E23: Tucson | F23: 85718 | G23: 6860460 | H23: Carondelet St. Joseph's Hospital | I23: 486 | K23: 1 | O23: No | P23: 1 | T23: No data | U23: Yes | W23: (520) 873-3000 | X23: =_xlfn.XLOOKUP(Burndata[[#This Row],[STATE_FULL]],'[1]State Regions'!$A:$A,'[1]State Regions'!$B:$B) -> West
A24: Arkansas | B24: AR | C24: Garland | D24: 300 Werner St | E24: Hot Springs | F24: 71913 | G24: 6710300 | H24: CHI St. Vincent Hospital Hot Springs | I24: 254 | K24: 1 | O24: No | Q24: 1 | T24: No data | U24: Yes | W24: (501) 622-1000 | X24: =_xlfn.XLOOKUP(Burndata[[#This Row],[STATE_FULL]],'[1]State Regions'!$A:$A,'[1]State Regions'!$B:$B) -> South
A25: Arkansas | B25: AR | C25: Pulaski | D25: 1 Children's Way | E25: Little Rock | F25: 72202 | G25: 6710340 | H25: Arkansas Children's Hospital (Arkansas Children's Hospital Burn Center) | I25: 336 | J25: 10 | L25: 1 | M25: 1 | N25: 1 | O25: Yes | R25: 1 | T25: No | U25: Yes | V25: No | W25: (501) 364-1323 | X25: =_xlfn.XLOOKUP(Burndata[[#This Row],[STATE_FULL]],'[1]State Regions'!$A:$A,'[1]State Regions'!$B:$B) -> South
A26: Arkansas | B26: AR | C26: Pulaski | D26: 4301 W Markham St | E26: Little Rock | F26: 72205 | G26: 6710440 | H26: UAMS Medical Center | I26: 522 | K26: 1 | O26: Yes | P26: 1 | T26: No data | U26: Yes | W26: (501) 686-7000 | X26: =_xlfn.XLOOKUP(Burndata[[#This Row],[STATE_FULL]],'[1]State Regions'!$A:$A,'[1]State Regions'!$B:$B) -> South
A27: Arkansas | B27: AR | C27: Pulaski | D27: 9601 Baptist Health Dr | E27: Little Rock | F27: 72205 | G27: 6710335 | H27: Baptist Health Medical Center | I27: 740 | K27: 1 | O27: No | Q27: 1 | T27: No data | U27: Yes | W27: (501) 202-2000 | X27: =_xlfn.XLOOKUP(Burndata[[#This Row],[STATE_FULL]],'[1]State Regions'!$A:$A,'[1]State Regions'!$B:$B) -> South
A28: Arkansas | B28: AR | C28: Pulaski | D28: 2 St Vincent Circle | E28: Little Rock | F28: 72205 | G28: 6710400 | H28: CHI St. Vincent Infirmary | I28: 600 | K28: 1 | O28: No | Q28: 1 | T28: No data | U28: Yes | W28: (501) 552-3000 | X28: =_xlfn.XLOOKUP(Burndata[[#This Row],[STATE_FULL]],'[1]State Regions'!$A:$A,'[1]State Regions'!$B:$B) -> South
A29: Arkansas | B29: AR | C29: Washington | D29: 3215 N Northhills Blvd | E29: Fayetteville | F29: 72703 | G29: 6710195 | H29: Washington Regional Medical Center | I29: 342 | K29: 1 | O29: No | Q29: 1 | T29: No data | U29: Yes | W29: (479) 463-1000 | X29: =_xlfn.XLOOKUP(Burndata[[#This Row],[STATE_FULL]],'[1]State Regions'!$A:$A,'[1]State Regions'!$B:$B) -> South
A30: California | B30: CA | C30: Alameda | D30: 1411 East 31st St | E30: Oakland | F30: 94602 | G30: 6930275 | H30: Highland Hospital | I30: 438 | K30: 1 | O30: Yes | P30: 1 | T30: No data | U30: Yes | W30: (510) 437-4800 | X30: =_xlfn.XLOOKUP(Burndata[[#This Row],[STATE_FULL]],'[1]State Regions'!$A:$A,'[1]State Regions'!$B:$B) -> West
A31: California | B31: CA | C31: Alameda | D31: 20103 Lake Chabot Rd | E31: Castro Valley | F31: 94546 | G31: 6930133 | H31: Sutter Health Eden Medical Center | I31: 122 | K31: 1 | O31: Yes | Q31: 1 | T31: No data | U31: Yes | W31: (510) 537-1234 | X31: =_xlfn.XLOOKUP(Burndata[[#This Row],[STATE_FULL]],'[1]State Regions'!$A:$A,'[1]State Regions'!$B:$B) -> West
A32: California | B32: CA | C32: Alameda | D32: 747 52nd St | E32: Oakland | F32: 94609 | G32: 6932180 | H32: UCSF Benioff Children's Hospital Oakland | I32: 191 | L32: 1 | O32: Yes | R32: 1 | T32: No data | U32: Yes | W32: (510) 428-3000 | X32: =_xlfn.XLOOKUP(Burndata[[#This Row],[STATE_FULL]],'[1]State Regions'!$A:$A,'[1]State Regions'!$B:$B) -> West
A33: California | B33: CA | C33: Butte | D33: 1531 Esplanade | E33: Chico | F33: 95926 | G33: 6930096 | H33: Enloe Medical Center | I33: 229 | K33: 1 | O33: Yes | Q33: 1 | T33: No data | U33: Yes | W33: (530) 332-7300 | X33: =_xlfn.XLOOKUP(Burndata[[#This Row],[STATE_FULL]],'[1]State Regions'!$A:$A,'[1]State Regions'!$B:$B) -> West
A34: California | B34: CA | C34: Contra Costa | D34: 1601 Ygnacio Valley Rd | E34: Walnut Creek | F34: 94598 | G34: 6933853 | H34: John Muir Medical Center, Walnut Creek | I34: 420 | K34: 1 | O34: Yes | Q34: 1 | T34: No data | U34: Yes | W34: (925) 939-3000 | X34: =_xlfn.XLOOKUP(Burndata[[#This Row],[STATE_FULL]],'[1]State Regions'!$A:$A,'[1]State Regions'!$B:$B) -> West
A35: California | B35: CA | C35: Fresno | D35: 2823 Fresno St | E35: Fresno | F35: 93721 | G35: 6930790 | H35: Community Regional Medical Center (Leon S. Peters Burn Center) | I35: 852 | J35: 10 | K35: 1 | M35: 1 | N35: 1 | O35: Yes | P35: 1 | T35: Yes | U35: Yes | V35: Yes | W35: (559) 459-6000 | X35: =_xlfn.XLOOKUP(Burndata[[#This Row],[STATE_FULL]],'[1]State Regions'!$A:$A,'[1]State Regions'!$B:$B) -> West
A36: California | B36: CA | C36: Kern | D36: 420 34th St | E36: Bakersfield | F36: 93301 | G36: 6930079 | H36: The Grossman Burn Center at Bakersfield Memorial Hospital | I36: 372 | J36: 7 | M36: 1 | N36: 1 | T36: Yes | V36: Yes | W36: (661) 323-2876 | X36: =_xlfn.XLOOKUP(Burndata[[#This Row],[STATE_FULL]],'[1]State Regions'!$A:$A,'[1]State Regions'!$B:$B) -> West
A37: California | B37: CA | C37: Los Angeles | D37: 1600 West Avenue J | E37: Lancaster | F37: 93534 | G37: 6931178 | H37: Antelope Valley Hospital | I37: 368 | K37: 1 | O37: Yes | Q37: 1 | T37: No data | U37: Yes | W37: (661) 949-5000 | X37: =_xlfn.XLOOKUP(Burndata[[#This Row],[STATE_FULL]],'[1]State Regions'!$A:$A,'[1]State Regions'!$B:$B) -> West
A38: California | B38: CA | C38: Los Angeles | D38: 8700 Beverly Blvd | E38: West Hollywood | F38: 90048 | G38: 6930444 | H38: Cedar-Sinai Medical Center | I38: 889 | K38: 1 | O38: Yes | P38: 1 | T38: No data | U38: Yes | W38: (310) 423-5000 | X38: =_xlfn.XLOOKUP(Burndata[[#This Row],[STATE_FULL]],'[1]State Regions'!$A:$A,'[1]State Regions'!$B:$B) -> West
A39: California | B39: CA | C39: Los Angeles | D39: 4650 Sunset Blvd | E39: Los Angeles | F39: 90027 | G39: 6931470 | H39: Children's Hospital Los Angeles | I39: 379 | L39: 1 | O39: Yes | R39: 1 | T39: No data | U39: Yes | W39: (323) 660-2450 | X39: =_xlfn.XLOOKUP(Burndata[[#This Row],[STATE_FULL]],'[1]State Regions'!$A:$A,'[1]State Regions'!$B:$B) -> West
A40: California | B40: CA | C40: Los Angeles | D40: 1798 North Garey Ave | E40: Pomona | F40: 91767 | G40: 6932450 | H40: Pomona Valley Hospital Medical Center | I40: 412 | K40: 1 | O40: Yes | Q40: 1 | T40: No data | U40: Yes | W40: (909) 865-9500 | X40: =_xlfn.XLOOKUP(Burndata[[#This Row],[STATE_FULL]],'[1]State Regions'!$A:$A,'[1]State Regions'!$B:$B) -> West
...

Sheet State Population (2026)
A1: Rank | B1: State | C1: Population (Jul 1, 2025) | D1: Population (Jul 1, 2024) | E1: Numeric Change | F1: % Change (2024–2025)
A2: 1 | B2: California | C2: 39355309 | D2: 39364774 | E2: =C2-D2 -> -9465 | F2: =(C2-D2)/D2 -> -0.0002404434
A3: 2 | B3: Texas | C3: 31709821 | D3: 31318578 | E3: =C3-D3 -> 391243 | F3: =(C3-D3)/D3 -> 0.012492362
A4: 3 | B4: Florida | C4: 23462518 | D4: 23265838 | E4: =C4-D4 -> 196680 | F4: =(C4-D4)/D4 -> 0.0084535962
A5: 4 | B5: New York | C5: 20002427 | D5: 20001419 | E5: =C5-D5 -> 1008 | F5: =(C5-D5)/D5 -> 5.0396424e-05
A6: 5 | B6: Pennsylvania | C6: 13059432 | D6: 13045848 | E6: =C6-D6 -> 13584 | F6: =(C6-D6)/D6 -> 0.0010412508
A7: 6 | B7: Illinois | C7: 12719141 | D7: 12703033 | E7: =C7-D7 -> 16108 | F7: =(C7-D7)/D7 -> 0.0012680436
A8: 7 | B8: Ohio | C8: 11900510 | D8: 11860621 | E8: =C8-D8 -> 39889 | F8: =(C8-D8)/D8 -> 0.003363146
A9: 8 | B9: Georgia | C9: 11302748 | D9: 11204208 | E9: =C9-D9 -> 98540 | F9: =(C9-D9)/D9 -> 0.0087949099
A10: 9 | B10: North Carolina | C10: 11197968 | D10: 11052061 | E10: =C10-D10 -> 145907 | F10: =(C10-D10)/D10 -> 0.013201791
A11: 10 | B11: Michigan | C11: 10127884 | D11: 10099962 | E11: =C11-D11 -> 27922 | F11: =(C11-D11)/D11 -> 0.0027645649
A12: 11 | B12: New Jersey | C12: 9548215 | D12: 9506354 | E12: =C12-D12 -> 41861 | F12: =(C12-D12)/D12 -> 0.0044034758
A13: 12 | B13: Virginia | C13: 8880107 | D13: 8819642 | E13: =C13-D13 -> 60465 | F13: =(C13-D13)/D13 -> 0.0068557204
... A51: 50 | B51: Wyoming | C51: 588753 | D51: 586722 | E51: =C51-D51 -> 2031 | F51: =(C51-D51)/D51 -> 0.0034616053
A52: — | B52: District of Columbia | C52: 693645 | D52: 691310 | E52: =C52-D52 -> 2335 | F52: =(C52-D52)/D52 -> 0.0033776453
B53: U.S. Total (50 States + D.C.) | C53: =SUM(C2:C52) -> 341784857 | D53: =SUM(D2:D52) -> 340003797 | E53: =C53-D53 -> 1781060 | F53: =(C53-D53)/D53 -> 0.0052383533

Sheet State Population (2025)
A1: U.S. State Population — Vintage 2025 Estimates (July 1, 2025)
A2: Source: U.S. Census Bureau, Vintage 2025 Population Estimates (Released January 27, 2026)
A4: Rank | B4: State | C4: Population (Jul 1, 2025) | D4: Population (Jul 1, 2024) | E4: Numeric Change | F4: % Change (2024–2025)
A5: 1 | B5: California | C5: 39355309 | D5: 39364774 | E5: =C5-D5 -> -9465 | F5: =(C5-D5)/D5 -> -0.0002404434
A6: 2 | B6: Texas | C6: 31709821 | D6: 31318578 | E6: =C6-D6 -> 391243 | F6: =(C6-D6)/D6 -> 0.012492362
A7: 3 | B7: Florida | C7: 23462518 | D7: 23265838 | E7: =C7-D7 -> 196680 | F7: =(C7-D7)/D7 -> 0.0084535962
A8: 4 | B8: New York | C8: 20002427 | D8: 20001419 | E8: =C8-D8 -> 1008 | F8: =(C8-D8)/D8 -> 5.0396424e-05
A9: 5 | B9: Pennsylvania | C9: 13059432 | D9: 13045848 | E9: =C9-D9 -> 13584 | F9: =(C9-D9)/D9 -> 0.0010412508
A10: 6 | B10: Illinois | C10: 12719141 | D10: 12703033 | E10: =C10-D10 -> 16108 | F10: =(C10-D10)/D10 -> 0.0012680436
A11: 7 | B11: Ohio | C11: 11900510 | D11: 11860621 | E11: =C11-D11 -> 39889 | F11: =(C11-D11)/D11 -> 0.003363146
A12: 8 | B12: Georgia | C12: 11302748 | D12: 11204208 | E12: =C12-D12 -> 98540 | F12: =(C12-D12)/D12 -> 0.0087949099
A13: 9 | B13: North Carolina | C13: 11197968 | D13: 11052061 | E13: =C13-D13 -> 145907 | F13: =(C13-D13)/D13 -> 0.013201791
A14: 10 | B14: Michigan | C14: 10127884 | D14: 10099962 | E14: =C14-D14 -> 27922 | F14: =(C14-D14)/D14 -> 0.0027645649
A15: 11 | B15: New Jersey | C15: 9548215 | D15: 9506354 | E15: =C15-D15 -> 41861 | F15: =(C15-D15)/D15 -> 0.0044034758
A16: 12 | B16: Virginia | C16: 8880107 | D16: 8819642 | E16: =C16-D16 -> 60465 | F16: =(C16-D16)/D16 -> 0.0068557204
... A54: 50 | B54: Wyoming | C54: 588753 | D54: 586722 | E54: =C54-D54 -> 2031 | F54: =(C54-D54)/D54 -> 0.0034616053
A55: — | B55: District of Columbia | C55: 693645 | D55: 691310 | E55: =C55-D55 -> 2335 | F55: =(C55-D55)/D55 -> 0.0033776453
B56: U.S. Total (50 States + D.C.) | C56: =SUM(C5:C55) -> 341784857 | D56: =SUM(D5:D55) -> 340003797 | E56: =C56-D56 -> 1781060 | F56: =(C56-D56)/D56 -> 0.0052383533

Sheet Top 10 Summary
A1: Top 10 States — Population & Children Rankings (Vintage 2025)
A2: Source: U.S. Census Bureau, Vintage 2025 Population Estimates (Released January 27, 2026)
A4: Top 10 States by Total Population (July 1, 2025)
A5: Rank | B5: State | C5: Population (Jul 1, 2025) | D5: % of U.S. Total | E5: YoY Change
A6: 1 | B6: California | C6: 39355309 | D6: 0.1151 | E6: -9465
A7: 2 | B7: Texas | C7: 31709821 | D7: 0.0928 | E7: 391243
A8: 3 | B8: Florida | C8: 23462518 | D8: 0.0686 | E8: 196680
A9: 4 | B9: New York | C9: 20002427 | D9: 0.0585 | E9: 1008
A10: 5 | B10: Pennsylvania | C10: 13059432 | D10: 0.0382 | E10: 13584
A11: 6 | B11: Illinois | C11: 12719141 | D11: 0.0372 | E11: 16108
A12: 7 | B12: Ohio | C12: 11900510 | D12: 0.0348 | E12: 39889
A13: 8 | B13: Georgia | C13: 11302748 | D13: 0.0331 | E13: 98540
A14: 9 | B14: North Carolina | C14: 11197968 | D14: 0.0328 | E14: 145907
A15: 10 | B15: Michigan | C15: 10127884 | D15: 0.0296 | E15: 27922
A18: Top 10 States by Children Under 18 Population (July 1, 2025)
A19: Children Rank | B19: State | C19: Children Under 18 | D19: % of State Population | E19: Total Population
A20: 1 | B20: California | C20: 8640000 | D20: 0.2195 | E20: 39355309
A21: 2 | B21: Texas | C21: 7930000 | D21: 0.2501 | E21: 31709821
A22: 3 | B22: Florida | C22: 4520000 | D22: 0.1926 | E22: 23462518
A23: 4 | B23: New York | C23: 4060000 | D23: 0.203 | E23: 20002427
A24: 5 | B24: Illinois | C24: 2730000 | D24: 0.2146 | E24: 12719141
A25: 6 | B25: Pennsylvania | C25: 2700000 | D25: 0.2067 | E25: 13059432
A26: 7 | B26: Georgia | C26: 2700000 | D26: 0.2389 | E26: 11302748
A27: 8 | B27: Ohio | C27: 2560000 | D27: 0.2151 | E27: 11900510
A28: 9 | B28: North Carolina | C28: 2510000 | D28: 0.2241 | E28: 11197968
A29: 10 | B29: Michigan | C29: 2180000 | D29: 0.2152 | E29: 10127884

Sheet Children Under 18 by State
A1: U.S. Population Under Age 18 by State — Vintage 2025 Estimates (July 1, 2025)
A2: Source: U.S. Census Bureau, Vintage 2025 Population Estimates (Released January 27, 2026) — Children Under 18 = Total Population minus 18+ Population
A4: Rank (Total Pop) | B4: State | C4: Total Population (Jul 1, 2025) | D4: Children Under 18 | E4: Adults 18+ | F4: Children % of Total | G4: Children Rank
A5: 1 | B5: California | C5: 39355309 | D5: 8640000 | E5: 30715309 | F5: =D5/C5 -> 0.21953836 | G5: 1
A6: 2 | B6: Texas | C6: 31709821 | D6: 7930000 | E6: 23779821 | F6: =D6/C6 -> 0.25008025 | G6: 2
A7: 3 | B7: Florida | C7: 23462518 | D7: 4520000 | E7: 18942518 | F7: =D7/C7 -> 0.19264769 | G7: 3
A8: 4 | B8: New York | C8: 20002427 | D8: 4060000 | E8: 15942427 | F8: =D8/C8 -> 0.20297537 | G8: 4
A9: 5 | B9: Pennsylvania | C9: 13059432 | D9: 2700000 | E9: 10359432 | F9: =D9/C9 -> 0.20674712 | G9: 6
A10: 6 | B10: Illinois | C10: 12719141 | D10: 2730000 | E10: 9989141 | F10: =D10/C10 -> 0.21463714 | G10: 5
A11: 7 | B11: Ohio | C11: 11900510 | D11: 2560000 | E11: 9340510 | F11: =D11/C11 -> 0.21511683 | G11: 8
A12: 8 | B12: Georgia | C12: 11302748 | D12: 2700000 | E12: 8602748 | F12: =D12/C12 -> 0.23887996 | G12: 7
A13: 9 | B13: North Carolina | C13: 11197968 | D13: 2510000 | E13: 8687968 | F13: =D13/C13 -> 0.22414781 | G13: 9
A14: 10 | B14: Michigan | C14: 10127884 | D14: 2180000 | E14: 7947884 | F14: =D14/C14 -> 0.21524733 | G14: 10
A15: 11 | B15: New Jersey | C15: 9548215 | D15: 2020000 | E15: 7528215 | F15: =D15/C15 -> 0.21155787 | G15: 11
A16: 12 | B16: Virginia | C16: 8880107 | D16: 1930000 | E16: 6950107 | F16: =D16/C16 -> 0.21733972 | G16: 12
... A54: 50 | B54: Wyoming | C54: 588753 | D54: 133000 | E54: 455753 | F54: =D54/C54 -> 0.22590118 | G54: 49
A55: — | B55: District of Columbia | C55: 693645 | D55: 104000 | E55: 589645 | F55: =D55/C55 -> 0.1499326 | G55: 51
B56: U.S. Total (50 States + D.C.) | C56: =SUM(C5:C55) -> 341784857 | D56: =SUM(D5:D55) -> 74671000 | E56: =SUM(E5:E55) -> 267113857 | F56: =D56/C56 -> 0.21847369
A58: Note: Children under 18 derived from SCPRC-EST2025-18+POP (Total Population minus 18+ Population). D.C. shown for reference only; not a state. Utah has the highest child share (~28%); D.C. lowest (~15%).

Sheet Data Table NIRD 20230130_orig
